2021-05-23 21:13:41,129 : ERROR : main :  : MAEFileUtils :  :  : Schrodinger Knime plugins: Neither SCHRODINGER environment nor preference is set. You can set SCHRODINGER installation location in the Schrodinger Preferences.
2021-05-23 21:13:41,130 : WARN  : main :  : SchrodFileUtils :  :  : SCHRODINGER is not set properly.
2021-05-23 21:13:41,131 : WARN  : Thread-7 :  : PythonService :  :  : PythonService is not initilized
2021-05-23 21:13:41,133 : WARN  : Thread-7 :  : PythonService :  :  : Failed to start python service.
2021-05-23 21:14:05,830 : WARN  : ForkJoinPool.commonPool-worker-1 :  : MoePreferencePage :  :  : Path to MOE not set in Preferences. Please check!
2021-05-23 21:19:37,298 : ERROR : KNIME-Worker-4-Python Source 3:1 :  : Node : Python Source : 3:1 : Execute failed: Could not start Python kernel. Error during Python installation test: Could not start Python executable at the given location (no_conda_environment_selected\python.exe): Cannot run program "no_conda_environment_selected\python.exe": CreateProcess error=2, The system cannot find the file specified
org.knime.python2.kernel.PythonInstallationTestException: Could not start Python kernel. Error during Python installation test: Could not start Python executable at the given location (no_conda_environment_selected\python.exe): Cannot run program "no_conda_environment_selected\python.exe": CreateProcess error=2, The system cannot find the file specified
	at org.knime.python2.kernel.PythonKernel.testInstallation(PythonKernel.java:380)
	at org.knime.python2.kernel.PythonKernel.<init>(PythonKernel.java:263)
	at org.knime.python2.kernel.PythonKernelQueue$KeyedPooledPythonKernelFactory.createKernel(PythonKernelQueue.java:351)
	at org.knime.python2.kernel.PythonKernelQueue$KeyedPooledPythonKernelFactory.populateHolder(PythonKernelQueue.java:344)
	at org.knime.python2.kernel.PythonKernelQueue$KeyedPooledPythonKernelFactory.makeObject(PythonKernelQueue.java:327)
	at org.knime.python2.kernel.PythonKernelQueue$KeyedPooledPythonKernelFactory.makeObject(PythonKernelQueue.java:1)
	at org.apache.commons.pool2.impl.GenericKeyedObjectPool.create(GenericKeyedObjectPool.java:1051)
	at org.apache.commons.pool2.impl.GenericKeyedObjectPool.borrowObject(GenericKeyedObjectPool.java:347)
	at org.apache.commons.pool2.impl.GenericKeyedObjectPool.borrowObject(GenericKeyedObjectPool.java:270)
	at org.knime.python2.kernel.PythonKernelQueue.dequeueHolder(PythonKernelQueue.java:244)
	at org.knime.python2.kernel.PythonKernelQueue.getNextKernelInternal(PythonKernelQueue.java:228)
	at org.knime.python2.kernel.PythonKernelQueue.getNextKernel(PythonKernelQueue.java:144)
	at org.knime.python2.nodes.PythonNodeModel.getNextKernelFromQueue(PythonNodeModel.java:138)
	at org.knime.python2.nodes.PythonNodeModel.getNextKernelFromQueue(PythonNodeModel.java:123)
	at org.knime.python2.nodes.source.PythonSourceNodeModel.execute(PythonSourceNodeModel.java:87)
	at org.knime.core.node.NodeModel.execute(NodeModel.java:747)
	at org.knime.core.node.NodeModel.executeModel(NodeModel.java:576)
	at org.knime.core.node.Node.invokeFullyNodeModelExecute(Node.java:1245)
	at org.knime.core.node.Node.execute(Node.java:1025)
	at org.knime.core.node.workflow.NativeNodeContainer.performExecuteNode(NativeNodeContainer.java:558)
	at org.knime.core.node.exec.LocalNodeExecutionJob.mainExecute(LocalNodeExecutionJob.java:95)
	at org.knime.core.node.workflow.NodeExecutionJob.internalRun(NodeExecutionJob.java:201)
	at org.knime.core.node.workflow.NodeExecutionJob.run(NodeExecutionJob.java:117)
	at org.knime.core.util.ThreadUtils$RunnableWithContextImpl.runWithContext(ThreadUtils.java:334)
	at org.knime.core.util.ThreadUtils$RunnableWithContext.run(ThreadUtils.java:210)
	at java.util.concurrent.Executors$RunnableAdapter.call(Executors.java:511)
	at java.util.concurrent.FutureTask.run(FutureTask.java:266)
	at org.knime.core.util.ThreadPool$MyFuture.run(ThreadPool.java:123)
	at org.knime.core.util.ThreadPool$Worker.run(ThreadPool.java:246)
2021-05-23 21:21:38,412 : ERROR : KNIME-Worker-5-Python Source 3:2 :  : Node : Python Source : 3:2 : Execute failed: ("NullPointerException"): null
java.lang.NullPointerException
	at de.mpicbg.knime.scripting.python.v2.AbstractPythonScriptingV2NodeModel.pullTableFromPython(AbstractPythonScriptingV2NodeModel.java:591)
	at de.mpicbg.knime.scripting.python.v2.AbstractPythonScriptingV2NodeModel.pullOutputFromPython(AbstractPythonScriptingV2NodeModel.java:481)
	at de.mpicbg.knime.scripting.python.v2.node.source.PythonSourceV2NodeModel.executeImpl(PythonSourceV2NodeModel.java:61)
	at de.mpicbg.knime.scripting.core.AbstractScriptingNodeModel.execute(AbstractScriptingNodeModel.java:176)
	at org.knime.core.node.NodeModel.executeModel(NodeModel.java:576)
	at org.knime.core.node.Node.invokeFullyNodeModelExecute(Node.java:1245)
	at org.knime.core.node.Node.execute(Node.java:1025)
	at org.knime.core.node.workflow.NativeNodeContainer.performExecuteNode(NativeNodeContainer.java:558)
	at org.knime.core.node.exec.LocalNodeExecutionJob.mainExecute(LocalNodeExecutionJob.java:95)
	at org.knime.core.node.workflow.NodeExecutionJob.internalRun(NodeExecutionJob.java:201)
	at org.knime.core.node.workflow.NodeExecutionJob.run(NodeExecutionJob.java:117)
	at org.knime.core.util.ThreadUtils$RunnableWithContextImpl.runWithContext(ThreadUtils.java:334)
	at org.knime.core.util.ThreadUtils$RunnableWithContext.run(ThreadUtils.java:210)
	at java.util.concurrent.Executors$RunnableAdapter.call(Executors.java:511)
	at java.util.concurrent.FutureTask.run(FutureTask.java:266)
	at org.knime.core.util.ThreadPool$MyFuture.run(ThreadPool.java:123)
	at org.knime.core.util.ThreadPool$Worker.run(ThreadPool.java:246)
2021-05-23 21:22:59,713 : ERROR : KNIME-Worker-6-Python Source 3:1 :  : Node : Python Source : 3:1 : Execute failed: Could not start Python kernel. Error during Python installation test: Could not start Python executable at the given location (no_conda_environment_selected\python.exe): Cannot run program "no_conda_environment_selected\python.exe": CreateProcess error=2, The system cannot find the file specified
org.knime.python2.kernel.PythonInstallationTestException: Could not start Python kernel. Error during Python installation test: Could not start Python executable at the given location (no_conda_environment_selected\python.exe): Cannot run program "no_conda_environment_selected\python.exe": CreateProcess error=2, The system cannot find the file specified
	at org.knime.python2.kernel.PythonKernel.testInstallation(PythonKernel.java:380)
	at org.knime.python2.kernel.PythonKernel.<init>(PythonKernel.java:263)
	at org.knime.python2.kernel.PythonKernelQueue$KeyedPooledPythonKernelFactory.createKernel(PythonKernelQueue.java:351)
	at org.knime.python2.kernel.PythonKernelQueue$KeyedPooledPythonKernelFactory.populateHolder(PythonKernelQueue.java:344)
	at org.knime.python2.kernel.PythonKernelQueue$KeyedPooledPythonKernelFactory.passivateObject(PythonKernelQueue.java:337)
	at org.knime.python2.kernel.PythonKernelQueue$KeyedPooledPythonKernelFactory.passivateObject(PythonKernelQueue.java:1)
	at org.apache.commons.pool2.impl.GenericKeyedObjectPool.returnObject(GenericKeyedObjectPool.java:483)
	at org.knime.python2.kernel.PythonKernelQueue.lambda$0(PythonKernelQueue.java:264)
	at java.lang.Thread.run(Thread.java:748)
2021-05-23 21:30:53,347 : ERROR : main :  : CollapseMetaNodeCommand :  :  : Collapsing to metanode failed: Cannot move all selected nodes (successor executing?).
java.lang.IllegalArgumentException: Cannot move all selected nodes (successor executing?).
	at org.knime.workbench.editor2.commands.CollapseMetaNodeCommand.create(CollapseMetaNodeCommand.java:202)
	at org.knime.workbench.editor2.actions.EncapsulateSubNodeAction.runInSWT(EncapsulateSubNodeAction.java:131)
	at org.knime.workbench.editor2.actions.AbstractNodeAction$1.run(AbstractNodeAction.java:160)
	at org.eclipse.swt.widgets.Synchronizer.syncExec(Synchronizer.java:236)
	at org.eclipse.ui.internal.UISynchronizer.syncExec(UISynchronizer.java:133)
	at org.eclipse.swt.widgets.Display.syncExec(Display.java:4561)
	at org.knime.workbench.editor2.actions.AbstractNodeAction.run(AbstractNodeAction.java:157)
	at org.eclipse.jface.action.Action.runWithEvent(Action.java:474)
	at org.eclipse.jface.action.ActionContributionItem.handleWidgetSelection(ActionContributionItem.java:579)
	at org.eclipse.jface.action.ActionContributionItem.lambda$4(ActionContributionItem.java:413)
	at org.eclipse.swt.widgets.EventTable.sendEvent(EventTable.java:89)
	at org.eclipse.swt.widgets.Display.sendEvent(Display.java:4105)
	at org.eclipse.swt.widgets.Widget.sendEvent(Widget.java:1037)
	at org.eclipse.swt.widgets.Display.runDeferredEvents(Display.java:3922)
	at org.eclipse.swt.widgets.Display.readAndDispatch(Display.java:3524)
	at org.eclipse.e4.ui.internal.workbench.swt.PartRenderingEngine$5.run(PartRenderingEngine.java:1160)
	at org.eclipse.core.databinding.observable.Realm.runWithDefault(Realm.java:338)
	at org.eclipse.e4.ui.internal.workbench.swt.PartRenderingEngine.run(PartRenderingEngine.java:1049)
	at org.eclipse.e4.ui.internal.workbench.E4Workbench.createAndRunUI(E4Workbench.java:155)
	at org.eclipse.ui.internal.Workbench.lambda$3(Workbench.java:658)
	at org.eclipse.core.databinding.observable.Realm.runWithDefault(Realm.java:338)
	at org.eclipse.ui.internal.Workbench.createAndRunWorkbench(Workbench.java:557)
	at org.eclipse.ui.PlatformUI.createAndRunWorkbench(PlatformUI.java:154)
	at org.knime.product.rcp.KNIMEApplication.start(KNIMEApplication.java:176)
	at org.eclipse.equinox.internal.app.EclipseAppHandle.run(EclipseAppHandle.java:203)
	at org.eclipse.core.runtime.internal.adaptor.EclipseAppLauncher.runApplication(EclipseAppLauncher.java:137)
	at org.eclipse.core.runtime.internal.adaptor.EclipseAppLauncher.start(EclipseAppLauncher.java:107)
	at org.eclipse.core.runtime.adaptor.EclipseStarter.run(EclipseStarter.java:401)
	at org.eclipse.core.runtime.adaptor.EclipseStarter.run(EclipseStarter.java:255)
	at sun.reflect.NativeMethodAccessorImpl.invoke0(Native Method)
	at sun.reflect.NativeMethodAccessorImpl.invoke(NativeMethodAccessorImpl.java:62)
	at sun.reflect.DelegatingMethodAccessorImpl.invoke(DelegatingMethodAccessorImpl.java:43)
	at java.lang.reflect.Method.invoke(Method.java:498)
	at org.eclipse.equinox.launcher.Main.invokeFramework(Main.java:657)
	at org.eclipse.equinox.launcher.Main.basicRun(Main.java:594)
	at org.eclipse.equinox.launcher.Main.run(Main.java:1447)
2021-05-23 21:30:59,654 : ERROR : main :  : CollapseMetaNodeCommand :  :  : Collapsing to metanode failed: Cannot move all selected nodes (successor executing?).
java.lang.IllegalArgumentException: Cannot move all selected nodes (successor executing?).
	at org.knime.workbench.editor2.commands.CollapseMetaNodeCommand.create(CollapseMetaNodeCommand.java:202)
	at org.knime.workbench.editor2.actions.CollapseMetaNodeAction.runInSWT(CollapseMetaNodeAction.java:134)
	at org.knime.workbench.editor2.actions.AbstractNodeAction$1.run(AbstractNodeAction.java:160)
	at org.eclipse.swt.widgets.Synchronizer.syncExec(Synchronizer.java:236)
	at org.eclipse.ui.internal.UISynchronizer.syncExec(UISynchronizer.java:133)
	at org.eclipse.swt.widgets.Display.syncExec(Display.java:4561)
	at org.knime.workbench.editor2.actions.AbstractNodeAction.run(AbstractNodeAction.java:157)
	at org.eclipse.jface.action.Action.runWithEvent(Action.java:474)
	at org.eclipse.jface.action.ActionContributionItem.handleWidgetSelection(ActionContributionItem.java:579)
	at org.eclipse.jface.action.ActionContributionItem.lambda$4(ActionContributionItem.java:413)
	at org.eclipse.swt.widgets.EventTable.sendEvent(EventTable.java:89)
	at org.eclipse.swt.widgets.Display.sendEvent(Display.java:4105)
	at org.eclipse.swt.widgets.Widget.sendEvent(Widget.java:1037)
	at org.eclipse.swt.widgets.Display.runDeferredEvents(Display.java:3922)
	at org.eclipse.swt.widgets.Display.readAndDispatch(Display.java:3524)
	at org.eclipse.e4.ui.internal.workbench.swt.PartRenderingEngine$5.run(PartRenderingEngine.java:1160)
	at org.eclipse.core.databinding.observable.Realm.runWithDefault(Realm.java:338)
	at org.eclipse.e4.ui.internal.workbench.swt.PartRenderingEngine.run(PartRenderingEngine.java:1049)
	at org.eclipse.e4.ui.internal.workbench.E4Workbench.createAndRunUI(E4Workbench.java:155)
	at org.eclipse.ui.internal.Workbench.lambda$3(Workbench.java:658)
	at org.eclipse.core.databinding.observable.Realm.runWithDefault(Realm.java:338)
	at org.eclipse.ui.internal.Workbench.createAndRunWorkbench(Workbench.java:557)
	at org.eclipse.ui.PlatformUI.createAndRunWorkbench(PlatformUI.java:154)
	at org.knime.product.rcp.KNIMEApplication.start(KNIMEApplication.java:176)
	at org.eclipse.equinox.internal.app.EclipseAppHandle.run(EclipseAppHandle.java:203)
	at org.eclipse.core.runtime.internal.adaptor.EclipseAppLauncher.runApplication(EclipseAppLauncher.java:137)
	at org.eclipse.core.runtime.internal.adaptor.EclipseAppLauncher.start(EclipseAppLauncher.java:107)
	at org.eclipse.core.runtime.adaptor.EclipseStarter.run(EclipseStarter.java:401)
	at org.eclipse.core.runtime.adaptor.EclipseStarter.run(EclipseStarter.java:255)
	at sun.reflect.NativeMethodAccessorImpl.invoke0(Native Method)
	at sun.reflect.NativeMethodAccessorImpl.invoke(NativeMethodAccessorImpl.java:62)
	at sun.reflect.DelegatingMethodAccessorImpl.invoke(DelegatingMethodAccessorImpl.java:43)
	at java.lang.reflect.Method.invoke(Method.java:498)
	at org.eclipse.equinox.launcher.Main.invokeFramework(Main.java:657)
	at org.eclipse.equinox.launcher.Main.basicRun(Main.java:594)
	at org.eclipse.equinox.launcher.Main.run(Main.java:1447)
2021-05-23 22:20:43,062 : WARN  : main :  : Node : CSV Writer : 3:5 : Please specify a file
2021-05-23 22:21:57,396 : WARN  : main :  : Node : PostgreSQL Connector : 3:6 : Database host is not defined.
2021-05-23 22:22:00,912 : WARN  : main :  : Node : PostgreSQL Connector (legacy) : 3:7 : No credentials or username for authentication given
2021-05-23 22:22:27,642 : WARN  : main :  : Node : PostgreSQL Connector : 3:8 : Database host is not defined.
2021-05-23 22:26:19,227 : ERROR : KNIME-Worker-40-Python Script 3:8 :  : Node : Python Script : 3:8 : Execute failed: name 'Selec_Columns' is not defined
Traceback (most recent call last):
File "<string>", line 8, in <module>
NameError: name 'Selec_Columns' is not defined

org.knime.python2.kernel.PythonIOException: name 'Selec_Columns' is not defined
Traceback (most recent call last):
File "<string>", line 8, in <module>
NameError: name 'Selec_Columns' is not defined

	at org.knime.python2.util.PythonUtils$Misc.executeCancelable(PythonUtils.java:296)
	at org.knime.python2.kernel.PythonKernel.executeCommandCancelable(PythonKernel.java:1479)
	at org.knime.python2.kernel.PythonKernel.execute(PythonKernel.java:1410)
	at org.knime.python2.nodes.script2.PythonScriptNodeModel2.execute(PythonScriptNodeModel2.java:139)
	at org.knime.core.node.NodeModel.executeModel(NodeModel.java:576)
	at org.knime.core.node.Node.invokeFullyNodeModelExecute(Node.java:1245)
	at org.knime.core.node.Node.execute(Node.java:1025)
	at org.knime.core.node.workflow.NativeNodeContainer.performExecuteNode(NativeNodeContainer.java:558)
	at org.knime.core.node.exec.LocalNodeExecutionJob.mainExecute(LocalNodeExecutionJob.java:95)
	at org.knime.core.node.workflow.NodeExecutionJob.internalRun(NodeExecutionJob.java:201)
	at org.knime.core.node.workflow.NodeExecutionJob.run(NodeExecutionJob.java:117)
	at org.knime.core.util.ThreadUtils$RunnableWithContextImpl.runWithContext(ThreadUtils.java:334)
	at org.knime.core.util.ThreadUtils$RunnableWithContext.run(ThreadUtils.java:210)
	at java.util.concurrent.Executors$RunnableAdapter.call(Executors.java:511)
	at java.util.concurrent.FutureTask.run(FutureTask.java:266)
	at org.knime.core.util.ThreadPool$MyFuture.run(ThreadPool.java:123)
	at org.knime.core.util.ThreadPool$Worker.run(ThreadPool.java:246)
Caused by: org.knime.python2.kernel.PythonIOException: name 'Selec_Columns' is not defined
Traceback (most recent call last):
File "<string>", line 8, in <module>
NameError: name 'Selec_Columns' is not defined

	at org.knime.python2.kernel.PythonKernel.executeCommand(PythonKernel.java:1468)
	at org.knime.python2.kernel.PythonKernel.execute(PythonKernel.java:1394)
	at org.knime.python2.kernel.PythonKernel.lambda$8(PythonKernel.java:1410)
	at java.util.concurrent.FutureTask.run(FutureTask.java:266)
	at java.util.concurrent.ThreadPoolExecutor.runWorker(ThreadPoolExecutor.java:1149)
	at java.util.concurrent.ThreadPoolExecutor$Worker.run(ThreadPoolExecutor.java:624)
	at java.lang.Thread.run(Thread.java:748)
Caused by: Traceback (most recent call last):
  File "D:\knime_4.3.1\plugins\org.knime.python2_4.3.1.v202101261634\py\messaging\RequestHandlers.py", line 96, in _handle_custom_message
    response = self._respond(message, response_message_id, workspace)
  File "D:\knime_4.3.1\plugins\org.knime.python2_4.3.1.v202101261634\py\messaging\RequestHandlers.py", line 376, in _respond
    output, error = workspace.execute(source_code, request.id)
  File "D:\knime_4.3.1\plugins\org.knime.python2_4.3.1.v202101261634\py\PythonKernelBase.py", line 289, in execute
    exec(source_code, self._exec_env, self._exec_env)
  File "<string>", line 8, in <module>
NameError: name 'Selec_Columns' is not defined

2021-05-23 22:34:15,129 : WARN  : main :  : Node : Table to PDF : 3:12 : Please specify a file
2021-05-24 04:44:43,547 : ERROR : main :  : MAEFileUtils :  :  : Schrodinger Knime plugins: Neither SCHRODINGER environment nor preference is set. You can set SCHRODINGER installation location in the Schrodinger Preferences.
2021-05-24 04:44:43,547 : WARN  : main :  : SchrodFileUtils :  :  : SCHRODINGER is not set properly.
2021-05-24 04:44:43,547 : WARN  : Thread-7 :  : PythonService :  :  : PythonService is not initilized
2021-05-24 04:44:43,547 : WARN  : Thread-7 :  : PythonService :  :  : Failed to start python service.
2021-05-24 04:45:13,065 : WARN  : ForkJoinPool.commonPool-worker-0 :  : MoePreferencePage :  :  : Path to MOE not set in Preferences. Please check!
2021-05-24 04:54:06,201 : ERROR : KNIME-Worker-19-Python Source 0:14 :  : Node : Python Source : 0:14 : Execute failed: output_table is not defined.
org.knime.python2.kernel.PythonIOException: output_table is not defined.
	at org.knime.python2.kernel.messaging.AbstractTaskHandler.handleFailureMessage(AbstractTaskHandler.java:146)
	at org.knime.python2.kernel.messaging.AbstractTaskHandler.handle(AbstractTaskHandler.java:92)
	at org.knime.python2.kernel.messaging.DefaultTaskFactory$DefaultTask.runInternal(DefaultTaskFactory.java:256)
	at java.util.concurrent.FutureTask.run(FutureTask.java:266)
	at java.util.concurrent.Executors$RunnableAdapter.call(Executors.java:511)
	at java.util.concurrent.FutureTask.run(FutureTask.java:266)
	at java.util.concurrent.ThreadPoolExecutor.runWorker(ThreadPoolExecutor.java:1149)
	at java.util.concurrent.ThreadPoolExecutor$Worker.run(ThreadPoolExecutor.java:624)
	at java.lang.Thread.run(Thread.java:748)
Caused by: Traceback (most recent call last):
  File "D:\knime_4.3.1\plugins\org.knime.python2_4.3.1.v202101261634\py\messaging\RequestHandlers.py", line 96, in _handle_custom_message
    response = self._respond(message, response_message_id, workspace)
  File "D:\knime_4.3.1\plugins\org.knime.python2_4.3.1.v202101261634\py\messaging\RequestHandlers.py", line 186, in _respond
    data_frame = workspace.get_variable(name)
  File "D:\knime_4.3.1\plugins\org.knime.python2_4.3.1.v202101261634\py\PythonKernelBase.py", line 187, in get_variable
    raise NameError(name + ' is not defined.')
NameError: output_table is not defined.

2021-05-24 04:54:26,586 : ERROR : KNIME-Worker-20-Python Source 0:14 :  : Node : Python Source : 0:14 : Execute failed: output_table is not defined.
org.knime.python2.kernel.PythonIOException: output_table is not defined.
	at org.knime.python2.kernel.messaging.AbstractTaskHandler.handleFailureMessage(AbstractTaskHandler.java:146)
	at org.knime.python2.kernel.messaging.AbstractTaskHandler.handle(AbstractTaskHandler.java:92)
	at org.knime.python2.kernel.messaging.DefaultTaskFactory$DefaultTask.runInternal(DefaultTaskFactory.java:256)
	at java.util.concurrent.FutureTask.run(FutureTask.java:266)
	at java.util.concurrent.Executors$RunnableAdapter.call(Executors.java:511)
	at java.util.concurrent.FutureTask.run(FutureTask.java:266)
	at java.util.concurrent.ThreadPoolExecutor.runWorker(ThreadPoolExecutor.java:1149)
	at java.util.concurrent.ThreadPoolExecutor$Worker.run(ThreadPoolExecutor.java:624)
	at java.lang.Thread.run(Thread.java:748)
Caused by: Traceback (most recent call last):
  File "D:\knime_4.3.1\plugins\org.knime.python2_4.3.1.v202101261634\py\messaging\RequestHandlers.py", line 96, in _handle_custom_message
    response = self._respond(message, response_message_id, workspace)
  File "D:\knime_4.3.1\plugins\org.knime.python2_4.3.1.v202101261634\py\messaging\RequestHandlers.py", line 186, in _respond
    data_frame = workspace.get_variable(name)
  File "D:\knime_4.3.1\plugins\org.knime.python2_4.3.1.v202101261634\py\PythonKernelBase.py", line 187, in get_variable
    raise NameError(name + ' is not defined.')
NameError: output_table is not defined.

2021-05-24 04:54:29,716 : ERROR : KNIME-Worker-21-Python Source 0:14 :  : Node : Python Source : 0:14 : Execute failed: output_table is not defined.
org.knime.python2.kernel.PythonIOException: output_table is not defined.
	at org.knime.python2.kernel.messaging.AbstractTaskHandler.handleFailureMessage(AbstractTaskHandler.java:146)
	at org.knime.python2.kernel.messaging.AbstractTaskHandler.handle(AbstractTaskHandler.java:92)
	at org.knime.python2.kernel.messaging.DefaultTaskFactory$DefaultTask.runInternal(DefaultTaskFactory.java:256)
	at java.util.concurrent.FutureTask.run(FutureTask.java:266)
	at java.util.concurrent.Executors$RunnableAdapter.call(Executors.java:511)
	at java.util.concurrent.FutureTask.run(FutureTask.java:266)
	at java.util.concurrent.ThreadPoolExecutor.runWorker(ThreadPoolExecutor.java:1149)
	at java.util.concurrent.ThreadPoolExecutor$Worker.run(ThreadPoolExecutor.java:624)
	at java.lang.Thread.run(Thread.java:748)
Caused by: Traceback (most recent call last):
  File "D:\knime_4.3.1\plugins\org.knime.python2_4.3.1.v202101261634\py\messaging\RequestHandlers.py", line 96, in _handle_custom_message
    response = self._respond(message, response_message_id, workspace)
  File "D:\knime_4.3.1\plugins\org.knime.python2_4.3.1.v202101261634\py\messaging\RequestHandlers.py", line 186, in _respond
    data_frame = workspace.get_variable(name)
  File "D:\knime_4.3.1\plugins\org.knime.python2_4.3.1.v202101261634\py\PythonKernelBase.py", line 187, in get_variable
    raise NameError(name + ' is not defined.')
NameError: output_table is not defined.

2021-05-24 04:55:01,759 : ERROR : KNIME-Worker-19-Python Source 0:14 :  : Node : Python Source : 0:14 : Execute failed: output_table is not defined.
org.knime.python2.kernel.PythonIOException: output_table is not defined.
	at org.knime.python2.kernel.messaging.AbstractTaskHandler.handleFailureMessage(AbstractTaskHandler.java:146)
	at org.knime.python2.kernel.messaging.AbstractTaskHandler.handle(AbstractTaskHandler.java:92)
	at org.knime.python2.kernel.messaging.DefaultTaskFactory$DefaultTask.runInternal(DefaultTaskFactory.java:256)
	at java.util.concurrent.FutureTask.run(FutureTask.java:266)
	at java.util.concurrent.Executors$RunnableAdapter.call(Executors.java:511)
	at java.util.concurrent.FutureTask.run(FutureTask.java:266)
	at java.util.concurrent.ThreadPoolExecutor.runWorker(ThreadPoolExecutor.java:1149)
	at java.util.concurrent.ThreadPoolExecutor$Worker.run(ThreadPoolExecutor.java:624)
	at java.lang.Thread.run(Thread.java:748)
Caused by: Traceback (most recent call last):
  File "D:\knime_4.3.1\plugins\org.knime.python2_4.3.1.v202101261634\py\messaging\RequestHandlers.py", line 96, in _handle_custom_message
    response = self._respond(message, response_message_id, workspace)
  File "D:\knime_4.3.1\plugins\org.knime.python2_4.3.1.v202101261634\py\messaging\RequestHandlers.py", line 186, in _respond
    data_frame = workspace.get_variable(name)
  File "D:\knime_4.3.1\plugins\org.knime.python2_4.3.1.v202101261634\py\PythonKernelBase.py", line 187, in get_variable
    raise NameError(name + ' is not defined.')
NameError: output_table is not defined.

2021-05-24 04:55:35,253 : ERROR : KNIME-Worker-20-Python Source 0:14 :  : Node : Python Source : 0:14 : Execute failed: output_table is not defined.
org.knime.python2.kernel.PythonIOException: output_table is not defined.
	at org.knime.python2.kernel.messaging.AbstractTaskHandler.handleFailureMessage(AbstractTaskHandler.java:146)
	at org.knime.python2.kernel.messaging.AbstractTaskHandler.handle(AbstractTaskHandler.java:92)
	at org.knime.python2.kernel.messaging.DefaultTaskFactory$DefaultTask.runInternal(DefaultTaskFactory.java:256)
	at java.util.concurrent.FutureTask.run(FutureTask.java:266)
	at java.util.concurrent.Executors$RunnableAdapter.call(Executors.java:511)
	at java.util.concurrent.FutureTask.run(FutureTask.java:266)
	at java.util.concurrent.ThreadPoolExecutor.runWorker(ThreadPoolExecutor.java:1149)
	at java.util.concurrent.ThreadPoolExecutor$Worker.run(ThreadPoolExecutor.java:624)
	at java.lang.Thread.run(Thread.java:748)
Caused by: Traceback (most recent call last):
  File "D:\knime_4.3.1\plugins\org.knime.python2_4.3.1.v202101261634\py\messaging\RequestHandlers.py", line 96, in _handle_custom_message
    response = self._respond(message, response_message_id, workspace)
  File "D:\knime_4.3.1\plugins\org.knime.python2_4.3.1.v202101261634\py\messaging\RequestHandlers.py", line 186, in _respond
    data_frame = workspace.get_variable(name)
  File "D:\knime_4.3.1\plugins\org.knime.python2_4.3.1.v202101261634\py\PythonKernelBase.py", line 187, in get_variable
    raise NameError(name + ' is not defined.')
NameError: output_table is not defined.

2021-05-24 04:55:45,031 : ERROR : KNIME-Worker-21-Python Source 0:14 :  : Node : Python Source : 0:14 : Execute failed: output_table is not defined.
org.knime.python2.kernel.PythonIOException: output_table is not defined.
	at org.knime.python2.kernel.messaging.AbstractTaskHandler.handleFailureMessage(AbstractTaskHandler.java:146)
	at org.knime.python2.kernel.messaging.AbstractTaskHandler.handle(AbstractTaskHandler.java:92)
	at org.knime.python2.kernel.messaging.DefaultTaskFactory$DefaultTask.runInternal(DefaultTaskFactory.java:256)
	at java.util.concurrent.FutureTask.run(FutureTask.java:266)
	at java.util.concurrent.Executors$RunnableAdapter.call(Executors.java:511)
	at java.util.concurrent.FutureTask.run(FutureTask.java:266)
	at java.util.concurrent.ThreadPoolExecutor.runWorker(ThreadPoolExecutor.java:1149)
	at java.util.concurrent.ThreadPoolExecutor$Worker.run(ThreadPoolExecutor.java:624)
	at java.lang.Thread.run(Thread.java:748)
Caused by: Traceback (most recent call last):
  File "D:\knime_4.3.1\plugins\org.knime.python2_4.3.1.v202101261634\py\messaging\RequestHandlers.py", line 96, in _handle_custom_message
    response = self._respond(message, response_message_id, workspace)
  File "D:\knime_4.3.1\plugins\org.knime.python2_4.3.1.v202101261634\py\messaging\RequestHandlers.py", line 186, in _respond
    data_frame = workspace.get_variable(name)
  File "D:\knime_4.3.1\plugins\org.knime.python2_4.3.1.v202101261634\py\PythonKernelBase.py", line 187, in get_variable
    raise NameError(name + ' is not defined.')
NameError: output_table is not defined.

2021-05-24 04:56:00,479 : ERROR : KNIME-Worker-19-Python Source 0:14 :  : Node : Python Source : 0:14 : Execute failed: output_table is not defined.
org.knime.python2.kernel.PythonIOException: output_table is not defined.
	at org.knime.python2.kernel.messaging.AbstractTaskHandler.handleFailureMessage(AbstractTaskHandler.java:146)
	at org.knime.python2.kernel.messaging.AbstractTaskHandler.handle(AbstractTaskHandler.java:92)
	at org.knime.python2.kernel.messaging.DefaultTaskFactory$DefaultTask.runInternal(DefaultTaskFactory.java:256)
	at java.util.concurrent.FutureTask.run(FutureTask.java:266)
	at java.util.concurrent.Executors$RunnableAdapter.call(Executors.java:511)
	at java.util.concurrent.FutureTask.run(FutureTask.java:266)
	at java.util.concurrent.ThreadPoolExecutor.runWorker(ThreadPoolExecutor.java:1149)
	at java.util.concurrent.ThreadPoolExecutor$Worker.run(ThreadPoolExecutor.java:624)
	at java.lang.Thread.run(Thread.java:748)
Caused by: Traceback (most recent call last):
  File "D:\knime_4.3.1\plugins\org.knime.python2_4.3.1.v202101261634\py\messaging\RequestHandlers.py", line 96, in _handle_custom_message
    response = self._respond(message, response_message_id, workspace)
  File "D:\knime_4.3.1\plugins\org.knime.python2_4.3.1.v202101261634\py\messaging\RequestHandlers.py", line 186, in _respond
    data_frame = workspace.get_variable(name)
  File "D:\knime_4.3.1\plugins\org.knime.python2_4.3.1.v202101261634\py\PythonKernelBase.py", line 187, in get_variable
    raise NameError(name + ' is not defined.')
NameError: output_table is not defined.

2021-05-24 04:59:13,177 : WARN  : KNIME-Worker-40-Python Source 0:17:0:16:0:1 :  : Node : Python Source : 0:17:0:16:0:1 : Execution canceled
2021-05-24 05:00:21,666 : WARN  : KNIME-Worker-42-Python Source 0:1 :  : Node : Python Source : 0:1 : Execution canceled
2021-05-24 05:07:55,332 : WARN  : KNIME-Worker-49-Python Source 0:1 :  : Node : Python Source : 0:1 : Execution canceled
2021-05-24 05:22:04,654 : ERROR : main :  : MAEFileUtils :  :  : Schrodinger Knime plugins: Neither SCHRODINGER environment nor preference is set. You can set SCHRODINGER installation location in the Schrodinger Preferences.
2021-05-24 05:22:04,654 : WARN  : main :  : SchrodFileUtils :  :  : SCHRODINGER is not set properly.
2021-05-24 05:22:04,659 : WARN  : Thread-7 :  : PythonService :  :  : PythonService is not initilized
2021-05-24 05:22:04,661 : WARN  : Thread-7 :  : PythonService :  :  : Failed to start python service.
2021-05-24 05:22:37,902 : WARN  : ForkJoinPool.commonPool-worker-0 :  : MoePreferencePage :  :  : Path to MOE not set in Preferences. Please check!
2021-05-24 15:31:40,443 : ERROR : main :  : MAEFileUtils :  :  : Schrodinger Knime plugins: Neither SCHRODINGER environment nor preference is set. You can set SCHRODINGER installation location in the Schrodinger Preferences.
2021-05-24 15:31:40,448 : WARN  : main :  : SchrodFileUtils :  :  : SCHRODINGER is not set properly.
2021-05-24 15:31:40,452 : WARN  : Thread-7 :  : PythonService :  :  : PythonService is not initilized
2021-05-24 15:31:40,457 : WARN  : Thread-7 :  : PythonService :  :  : Failed to start python service.
2021-05-24 15:32:19,518 : WARN  : Worker-2: Workflow Coach loader :  : MoePreferencePage :  :  : Path to MOE not set in Preferences. Please check!
